Workbook

Sheet Details
B3: Name of Administrator/ Insurance Company :
B5: Principal Officer/ Contact person:
B6: Contact Details - Address (Head office)
B7: - Landlines/Cell/Fax
B8: - E-mail address
B9: -Branches ( Addresses)
B10: Name of Official Completing the Return:
B11: Designation:
B12: Reporting Date
B15: Changes in Management or Board of Directors of the Administrator/ Insurer
B16: Appointed
B17: Name of official | C17: Position | D17: Date
B22: Retired/Resigned
B23: Name of official | C23: Position | D23: Date

Sheet Profit and loss
A1: Administrator Name
A3: Statement of Proit or Loss
A4: For the Quarter ended XX XXX 2022
B5: ZW$ | C5: US$
A6: INCOME
A7: Fund Administration fees | B7: 0 | C7: 0
A8: Cost of Guarantee | B8: 0 | C8: 0
A9: Other income (specify) | B9: 0 | C9: 0
A10: Other income (specify) | B10: 0 | C10: 0
A11: Other income (specify) | B11: 0 | C11: 0
A12: Other income (specify)
A13: Other income (specify) | B13: 0 | C13: 0
A15: Total Income | B15: =SUM(B7:B13) -> 0 | C15: =SUM(C7:C13) -> 0
A17: EXPENSES
A18: Advertising and business promotions | B18: 0 | C18: 0
A19: Audit and accounting fees | B19: 0 | C19: 0
A20: Bank Charges | B20: 0 | C20: 0
A21: Salaries | B21: 0 | C21: 0
A22: Other staff costs | B22: 0 | C22: 0
A23: Travel and entertainment | B23: 0 | C23: 0
A24: Computer consumables | B24: 0 | C24: 0
A25: Consultancy fees | B25: 0 | C25: 0
A26: Depreciation | B26: 0 | C26: 0
A27: Board costs | B27: 0 | C27: 0
A28: Rates | B28: 0 | C28: 0
A29: Insurance and licences | B29: 0 | C29: 0
... A38: Other (specify) | B38: 0 | C38: 0
A40: Total Expenses | B40: =SUM(B18:B38) -> 0 | C40: =SUM(C18:C38) -> 0
A42: Profit / Loss for the period | B42: =+B15-B40 -> 0 | C42: =+C15-C40 -> 0
A44: Note
A45: Record item in the currency in which business is transacted

Sheet Balance Sheet
A1: Administrator Name
A3: Statement of Financial Position
A4: For the Quarter ended XX XXX 2022
B6: ZW$
A7: Assets
A8: Non current assets
A9: Property and Equipment | B9: 0
A10: Equities | B10: 0
A11: Bonds | B11: 0
A12: Deferred tax asset | B12: 0
A13: Other (specify) | B13: 0
A14: Other (specify) | B14: 0
A15: Total Non current assets | B15: =+SUM(B9:B14) -> 0
A17: Current Assets
A18: Debtors | B18: 0
A19: Stock | B19: 0
A20: Money market investments | B20: 0
A21: Bank and cash balances | B21: 0
A22: Other (specify) | B22: 0
A23: Other (specify) | B23: 0
A24: Total current assets | B24: =+SUM(B18:B23) -> 0
A26: Total Assets
A28: Equity and Liabilities
A29: Non current liabilities
A30: Long - term loans | B30: 0
A31: Deferred tax liabilities | B31: 0
A32: Other (specify) | B32: 0
A33: Other (specify) | B33: 0
A34: Total non current liabilities | B34: =+SUM(B30:B33) -> 0
A36: Current liabilities
A37: Creditors | B37: 0
A38: Current tax payable | B38: 0
A39: Leave liability | B39: 0
A40: Other (specify) | B40: 0
A41: Other (specify) | B41: 0
A42: Total current liabilities | B42: =+SUM(B37:B41) -> 0
A44: Total Liabilities | B44: =+B34+B42 -> 0
A46: Equity
A47: Share capital | B47: 0
A48: Share premium | B48: 0
...

Sheet List of funds and fees 
A1: Administrator Name
A5: Pension Fund Name | B5: Type of Fund (DC/DB) | C5: Self Administered / Insured | D5: Fund status (Active / Paid Up / Dissolved) | E5: Admin fees charged
E6: ZW$ | F6: USD
A7: XXXX | E7: 0 | F7: 0
A8: XXXX | E8: 0 | F8: 0
A9: XXXX | E9: 0 | F9: 0
A10: XXXX | E10: 0 | F10: 0
A11: XXXX | E11: 0 | F11: 0
A12: XXXX | E12: 0 | F12: 0
A13: XXXX | E13: 0 | F13: 0
A14: XXXX | E14: 0 | F14: 0
A15: XXXX | E15: 0 | F15: 0
A17: Total Administration Fees | E17: =SUM(E6:E16) -> 0 | F17: =SUM(F6:F16) -> 0
A19: Note
A20: Record item in the currency in which business is transacted

Sheet Debtors' Schedule 
A1: Administrator Name
A5: Pension Fund Name | B5: 30 days and below | C5: between 31 days and 60 days | D5: between 61 days and 90 days | E5: 91 days and above | F5: Total
A6: XXXX | F6: =SUM(B6:E6) -> 0
A7: =+'List of funds and fees '!A7 -> XXXX | F7: =SUM(B7:E7) -> 0
A8: =+'List of funds and fees '!A8 -> XXXX | F8: =SUM(B8:E8) -> 0
A9: =+'List of funds and fees '!A9 -> XXXX | F9: =SUM(B9:E9) -> 0
A10: =+'List of funds and fees '!A10 -> XXXX | F10: =SUM(B10:E10) -> 0
A11: =+'List of funds and fees '!A11 -> XXXX | F11: =SUM(B11:E11) -> 0
A12: =+'List of funds and fees '!A12 -> XXXX | F12: =SUM(B12:E12) -> 0
A13: =+'List of funds and fees '!A13 -> XXXX | F13: =SUM(B13:E13) -> 0
A14: =+'List of funds and fees '!A14 -> XXXX | F14: =SUM(B14:E14) -> 0
A15: =+'List of funds and fees '!A15 -> XXXX | F15: =SUM(B15:E15) -> 0
A17: Total | B17: =SUM(B6:B15) -> 0 | C17: =SUM(C6:C15) -> 0 | D17: =SUM(D6:D15) -> 0 | E17: =SUM(E6:E15) -> 0 | F17: =SUM(F6:F15) -> 0

Sheet Transfers 
A1: Administrator Name
A5: TRANSFERS IN
B7: Name of Fund | C7: Date of Transfer | D7: Former Administrator | E7: Value of Assets Received | F7: Value of Assets Outstanding
B13: Total Assets Transferred In | E13: =SUM(E8:E12) -> 0 | F13: =SUM(F8:F12) -> 0
A16: TRANSFERS OUT
B18: Name of Fund | C18: Date of Transfer | D18: Name of New Administrator | E18: Value of Assets Transferred | F18: Value of Assets Outstanding
B24: Total Assets Transferred Out | E24: =SUM(E19:E23) -> 0 | F24: =SUM(F19:F23) -> 0

Sheet Dissolutions
A1: Administrator Name
A5: DISSOLUTIONS
B7: Name of Fund | C7: Date of Dissolution Approval | D7: Name of liquidator | E7: Number of members | F7: Value of Assets | G7: Stage of Dissolution
F8: 0
F9: 0
F10: 0
F11: 0
F12: 0
